Loading .env environment variables...
Ignoring exception in on_message
Traceback (most recent call last):
  File "/home/pi/.local/share/virtualenvs/sintyokuBot-edrrt-H1/lib/python3.9/site-packages/discord/client.py", line 343, in _run_event
    await coro(*args, **kwargs)
  File "/home/pi/sintyokuBot/sintyokuBot.py", line 168, in on_message
    if message.author.voice == None:
AttributeError: 'User' object has no attribute 'voice'
Ignoring exception in on_message
Traceback (most recent call last):
  File "/home/pi/.local/share/virtualenvs/sintyokuBot-edrrt-H1/lib/python3.9/site-packages/discord/client.py", line 343, in _run_event
    await coro(*args, **kwargs)
  File "/home/pi/sintyokuBot/sintyokuBot.py", line 168, in on_message
    if message.author.voice == None:
AttributeError: 'User' object has no attribute 'voice'
Ignoring exception in on_message
Traceback (most recent call last):
  File "/home/pi/.local/share/virtualenvs/sintyokuBot-edrrt-H1/lib/python3.9/site-packages/discord/client.py", line 343, in _run_event
    await coro(*args, **kwargs)
  File "/home/pi/sintyokuBot/sintyokuBot.py", line 168, in on_message
    if message.author.voice == None:
AttributeError: 'User' object has no attribute 'voice'
Ignoring exception in on_message
Traceback (most recent call last):
  File "/home/pi/.local/share/virtualenvs/sintyokuBot-edrrt-H1/lib/python3.9/site-packages/discord/client.py", line 343, in _run_event
    await coro(*args, **kwargs)
  File "/home/pi/sintyokuBot/sintyokuBot.py", line 168, in on_message
    if message.author.voice == None:
AttributeError: 'User' object has no attribute 'voice'
Ignoring exception in on_message
Traceback (most recent call last):
  File "/home/pi/.local/share/virtualenvs/sintyokuBot-edrrt-H1/lib/python3.9/site-packages/discord/client.py", line 343, in _run_event
    await coro(*args, **kwargs)
  File "/home/pi/sintyokuBot/sintyokuBot.py", line 168, in on_message
    if message.author.voice == None:
AttributeError: 'User' object has no attribute 'voice'
Ignoring exception in on_message
Traceback (most recent call last):
  File "/home/pi/.local/share/virtualenvs/sintyokuBot-edrrt-H1/lib/python3.9/site-packages/discord/client.py", line 343, in _run_event
    await coro(*args, **kwargs)
  File "/home/pi/sintyokuBot/sintyokuBot.py", line 168, in on_message
    if message.author.voice == None:
AttributeError: 'User' object has no attribute 'voice'
Ignoring exception in on_message
Traceback (most recent call last):
  File "/home/pi/.local/share/virtualenvs/sintyokuBot-edrrt-H1/lib/python3.9/site-packages/discord/client.py", line 343, in _run_event
    await coro(*args, **kwargs)
  File "/home/pi/sintyokuBot/sintyokuBot.py", line 168, in on_message
    if message.author.voice == None:
AttributeError: 'User' object has no attribute 'voice'
Ignoring exception in on_message
Traceback (most recent call last):
  File "/home/pi/.local/share/virtualenvs/sintyokuBot-edrrt-H1/lib/python3.9/site-packages/discord/client.py", line 343, in _run_event
    await coro(*args, **kwargs)
  File "/home/pi/sintyokuBot/sintyokuBot.py", line 168, in on_message
    if message.author.voice == None:
AttributeError: 'User' object has no attribute 'voice'
Ignoring exception in on_message
Traceback (most recent call last):
  File "/home/pi/.local/share/virtualenvs/sintyokuBot-edrrt-H1/lib/python3.9/site-packages/discord/client.py", line 343, in _run_event
    await coro(*args, **kwargs)
  File "/home/pi/sintyokuBot/sintyokuBot.py", line 168, in on_message
    if message.author.voice == None:
AttributeError: 'User' object has no attribute 'voice'
Ignoring exception in on_message
Traceback (most recent call last):
  File "/home/pi/.local/share/virtualenvs/sintyokuBot-edrrt-H1/lib/python3.9/site-packages/discord/client.py", line 343, in _run_event
    await coro(*args, **kwargs)
  File "/home/pi/sintyokuBot/sintyokuBot.py", line 168, in on_message
    if message.author.voice == None:
AttributeError: 'User' object has no attribute 'voice'
Ignoring exception in on_message
Traceback (most recent call last):
  File "/home/pi/.local/share/virtualenvs/sintyokuBot-edrrt-H1/lib/python3.9/site-packages/discord/client.py", line 343, in _run_event
    await coro(*args, **kwargs)
  File "/home/pi/sintyokuBot/sintyokuBot.py", line 168, in on_message
    if message.author.voice == None:
AttributeError: 'User' object has no attribute 'voice'
Ignoring exception in on_message
Traceback (most recent call last):
  File "/home/pi/.local/share/virtualenvs/sintyokuBot-edrrt-H1/lib/python3.9/site-packages/discord/client.py", line 343, in _run_event
    await coro(*args, **kwargs)
  File "/home/pi/sintyokuBot/sintyokuBot.py", line 168, in on_message
    if message.author.voice == None:
AttributeError: 'User' object has no attribute 'voice'
Ignoring exception in on_message
Traceback (most recent call last):
  File "/home/pi/.local/share/virtualenvs/sintyokuBot-edrrt-H1/lib/python3.9/site-packages/discord/client.py", line 343, in _run_event
    await coro(*args, **kwargs)
  File "/home/pi/sintyokuBot/sintyokuBot.py", line 168, in on_message
    if message.author.voice == None:
AttributeError: 'User' object has no attribute 'voice'
Ignoring exception in on_message
Traceback (most recent call last):
  File "/home/pi/.local/share/virtualenvs/sintyokuBot-edrrt-H1/lib/python3.9/site-packages/discord/client.py", line 343, in _run_event
    await coro(*args, **kwargs)
  File "/home/pi/sintyokuBot/sintyokuBot.py", line 168, in on_message
    if message.author.voice == None:
AttributeError: 'User' object has no attribute 'voice'
Ignoring exception in on_message
Traceback (most recent call last):
  File "/home/pi/.local/share/virtualenvs/sintyokuBot-edrrt-H1/lib/python3.9/site-packages/discord/client.py", line 343, in _run_event
    await coro(*args, **kwargs)
  File "/home/pi/sintyokuBot/sintyokuBot.py", line 168, in on_message
    if message.author.voice == None:
AttributeError: 'User' object has no attribute 'voice'
Ignoring exception in on_message
Traceback (most recent call last):
  File "/home/pi/.local/share/virtualenvs/sintyokuBot-edrrt-H1/lib/python3.9/site-packages/discord/client.py", line 343, in _run_event
    await coro(*args, **kwargs)
  File "/home/pi/sintyokuBot/sintyokuBot.py", line 168, in on_message
    if message.author.voice == None:
AttributeError: 'User' object has no attribute 'voice'
Ignoring exception in on_message
Traceback (most recent call last):
  File "/home/pi/.local/share/virtualenvs/sintyokuBot-edrrt-H1/lib/python3.9/site-packages/discord/client.py", line 343, in _run_event
    await coro(*args, **kwargs)
  File "/home/pi/sintyokuBot/sintyokuBot.py", line 168, in on_message
    if message.author.voice == None:
AttributeError: 'User' object has no attribute 'voice'
